<?xml version="1.0" ?>
<!-- =================================================================================== -->
<!-- |    This document was autogenerated by xacro from kr10.xacro                     | -->
<!-- |    EDITING THIS FILE BY HAND IS NOT RECOMMENDED                                 | -->
<!-- =================================================================================== -->
<robot name="kuka_kr10" xmlns:xacro="http://ros.org/wiki/xacro">
  <!-- colours based on RAL values given in "FAQ - Colours of robot and robot
       controller", version "KUKA.Tifs | 2010-01-21 |YM| DefaultColorsRobotAndController.doc",
       downloaded 2015-07-18 from
       http://www.kuka.be/main/cservice/faqs/hardware/DefaultColorsRobotAndController.pdf

       all RAL colours converted using http://www.visual-graphics.de/en/customer-care/ral-colours
  -->
  <!-- default colors for robots -->
  <!-- RAL 2003: mechanical arm (pastel orange) -->
  <!-- RAL 9005: robot base (jet black) -->
  <!-- RAL 7022: pedestal frame (olive grey) -->
  <!-- default colors for KR C2 controller cabinets -->
  <!-- RAL 7016 (anthracite gray) -->
  <!-- optional colors -->
  <!-- RAL 1004 - golden -->
  <!-- RAL 1006 - corn yellow -->
  <!-- RAL 1013 - pearly white -->
  <!-- RAL 1015 - light ivory -->
  <!-- RAL 2000 - yellow orange -->
  <!-- RAL 2008 - light orange -->
  <!-- RAL 3002 - carmine -->
  <!-- RAL 3004 - crimson -->
  <!-- RAL 3005 - claret red -->
  <!-- RAL 4009 - pastel mauve -->
  <!-- RAL 5000 - purple blue -->
  <!-- RAL 5001 - greenish blue -->
  <!-- RAL 5002 - ultramarine -->
  <!-- RAL 5005 - signal blue -->
  <!-- RAL 5007 - luminous blue -->
  <!-- RAL 5012 - light blau -->
  <!-- RAL 5018 - turquoise blue -->
  <!-- RAL 6011 - mignonette green -->
  <!-- RAL 6021 - celadon -->
  <!-- RAL 6034 - pastel green -->
  <!-- RAL 7001 - silver gray -->
  <!-- RAL 7011 - ferric gray -->
  <!-- RAL 7032 - silicic gray -->
  <!-- RAL 7035 - light gray -->
  <!-- RAL 7038 - agate gray -->
  <!-- RAL 9001 - cream white -->
  <!-- RAL 9002 - gray white  -->
  <!-- get base kuka kr10 model -->
  <link name="base_link">
    <visual>
      <origin rpy="0 0 0" xyz="0 0 0"/>
      <geometry>
        <mesh filename="package://kuka_kr10_support/meshes/kr10r1100sixx/visual/base.stl"/>
      </geometry>
      <material name="">
        <color rgba="0.0549019607843 0.0549019607843 0.0627450980392 1.0"/>
      </material>
    </visual>
    <collision>
      <origin rpy="0 0 0" xyz="0 0 0"/>
      <geometry>
        <mesh filename="package://kuka_kr10_support/meshes/kr10r1100sixx/collision/base.stl"/>
      </geometry>
    </collision>
  </link>
  <link name="link_1">
    <visual>
      <origin rpy="0 0 0" xyz="0 0 0"/>
      <geometry>
        <mesh filename="package://kuka_kr10_support/meshes/kr10r1100sixx/visual/link_1.stl"/>
      </geometry>
      <material name="">
        <color rgba="0.964705882353 0.470588235294 0.156862745098 1.0"/>
      </material>
    </visual>
    <collision>
      <origin rpy="0 0 0" xyz="0 0 0"/>
      <geometry>
        <mesh filename="package://kuka_kr10_support/meshes/kr10r1100sixx/collision/link_1.stl"/>
      </geometry>
    </collision>
  </link>
  <link name="link_2">
    <visual>
      <origin rpy="0 0 0" xyz="0 0 0"/>
      <geometry>
        <mesh filename="package://kuka_kr10_support/meshes/kr10r1100sixx/visual/link_2.stl"/>
      </geometry>
      <material name="">
        <color rgba="0.964705882353 0.470588235294 0.156862745098 1.0"/>
      </material>
    </visual>
    <collision>
      <origin rpy="0 0 0" xyz="0 0 0"/>
      <geometry>
        <mesh filename="package://kuka_kr10_support/meshes/kr10r1100sixx/collision/link_2.stl"/>
      </geometry>
    </collision>
  </link>
  <link name="link_3">
    <visual>
      <origin rpy="0 0 0" xyz="0 0 0"/>
      <geometry>
        <mesh filename="package://kuka_kr10_support/meshes/kr10r1100sixx/visual/link_3.stl"/>
      </geometry>
      <material name="">
        <color rgba="0.964705882353 0.470588235294 0.156862745098 1.0"/>
      </material>
    </visual>
    <collision>
      <origin rpy="0 0 0" xyz="0 0 0"/>
      <geometry>
        <mesh filename="package://kuka_kr10_support/meshes/kr10r1100sixx/collision/link_3.stl"/>
      </geometry>
    </collision>
  </link>
  <link name="link_4">
    <visual>
      <origin rpy="0 0 0" xyz="0 0 0"/>
      <geometry>
        <mesh filename="package://kuka_kr10_support/meshes/kr10r1100sixx/visual/link_4.stl"/>
      </geometry>
      <material name="">
        <color rgba="0.964705882353 0.470588235294 0.156862745098 1.0"/>
      </material>
    </visual>
    <collision>
      <origin rpy="0 0 0" xyz="0 0 0"/>
      <geometry>
        <mesh filename="package://kuka_kr10_support/meshes/kr10r1100sixx/collision/link_4.stl"/>
      </geometry>
    </collision>
  </link>
  <link name="link_5">
    <visual>
      <origin rpy="0 0 0" xyz="0 0 0"/>
      <geometry>
        <mesh filename="package://kuka_kr10_support/meshes/kr10r1100sixx/visual/link_5.stl"/>
      </geometry>
      <material name="">
        <color rgba="0.964705882353 0.470588235294 0.156862745098 1.0"/>
      </material>
    </visual>
    <collision>
      <origin rpy="0 0 0" xyz="0 0 0"/>
      <geometry>
        <mesh filename="package://kuka_kr10_support/meshes/kr10r1100sixx/collision/link_5.stl"/>
      </geometry>
    </collision>
  </link>
  <link name="link_6">
    <visual>
      <origin rpy="0 0 0" xyz="0 0 0"/>
      <geometry>
        <mesh filename="package://kuka_kr10_support/meshes/kr10r1100sixx/visual/link_6.stl"/>
      </geometry>
      <material name="">
        <color rgba="0.505882352941 0.470588235294 0.388235294118 1.0"/>
      </material>
    </visual>
    <collision>
      <origin rpy="0 0 0" xyz="0 0 0"/>
      <geometry>
        <mesh filename="package://kuka_kr10_support/meshes/kr10r1100sixx/collision/link_6.stl"/>
      </geometry>
    </collision>
  </link>
  <!-- This frame corresponds to the $FLANGE coordinate system in KUKA KRC controllers. -->
  <link name="tool0"/>
  <joint name="joint_a1" type="revolute">
    <origin rpy="0 0 0" xyz="0 0 0.400"/>
    <parent link="base_link"/>
    <child link="link_1"/>
    <axis xyz="0 0 -1"/>
    <limit effort="0" lower="-2.96705972839" upper="2.96705972839" velocity="6.28318530718"/>
  </joint>
  <joint name="joint_a2" type="revolute">
    <origin rpy="0 0 0" xyz="0.025 0 0"/>
    <parent link="link_1"/>
    <child link="link_2"/>
    <axis xyz="0 1 0"/>
    <limit effort="0" lower="-3.31612557879" upper="0.785398163397" velocity="5.23598775598"/>
  </joint>
  <joint name="joint_a3" type="revolute">
    <origin rpy="0 0 0" xyz="0.560 0 0"/>
    <parent link="link_2"/>
    <child link="link_3"/>
    <axis xyz="0 1 0"/>
    <limit effort="0" lower="-2.09439510239" upper="2.72271363311" velocity="6.28318530718"/>
  </joint>
  <joint name="joint_a4" type="revolute">
    <origin rpy="0 0 0" xyz="0 0 0.035"/>
    <parent link="link_3"/>
    <child link="link_4"/>
    <axis xyz="-1 0 0"/>
    <limit effort="0" lower="-3.22885911619" upper="3.22885911619" velocity="6.6497044501"/>
  </joint>
  <joint name="joint_a5" type="revolute">
    <origin rpy="0 0 0" xyz="0.515 0 0"/>
    <parent link="link_4"/>
    <child link="link_5"/>
    <axis xyz="0 1 0"/>
    <limit effort="0" lower="-2.09439510239" upper="2.09439510239" velocity="6.77187749774"/>
  </joint>
  <joint name="joint_a6" type="revolute">
    <origin rpy="0 0 0" xyz="0.080 0 0"/>
    <parent link="link_5"/>
    <child link="link_6"/>
    <axis xyz="-1 0 0"/>
    <limit effort="0" lower="-6.10865238198" upper="6.10865238198" velocity="10.7337748998"/>
  </joint>
  <joint name="joint_a6-tool0" type="fixed">
    <parent link="link_6"/>
    <child link="tool0"/>
    <origin rpy="0 1.57079632679 0" xyz="0 0 0"/>
  </joint>
  <!-- ROS base_link to KUKA $ROBROOT coordinate system transform -->
  <link name="base"/>
  <joint name="base_link-base" type="fixed">
    <origin rpy="0 0 0" xyz="0 0 0"/>
    <parent link="base_link"/>
    <child link="base"/>
  </joint>
  <!-- transmission list -->
  <transmission name="tran1">
    <type>transmission_interface/SimpleTransmission</type>
    <joint name="joint_a1">
      <hardwareInterface>PositionJointInterface</hardwareInterface>
    </joint>
    <actuator name="motor1">
      <mechanicalReduction>1</mechanicalReduction>
    </actuator>
  </transmission>
  <transmission name="tran2">
    <type>transmission_interface/SimpleTransmission</type>
    <joint name="joint_a2">
      <hardwareInterface>PositionJointInterface</hardwareInterface>
    </joint>
    <actuator name="motor2">
      <mechanicalReduction>1</mechanicalReduction>
    </actuator>
  </transmission>
  <transmission name="tran3">
    <type>transmission_interface/SimpleTransmission</type>
    <joint name="joint_a3">
      <hardwareInterface>PositionJointInterface</hardwareInterface>
    </joint>
    <actuator name="motor3">
      <mechanicalReduction>1</mechanicalReduction>
    </actuator>
  </transmission>
  <transmission name="tran4">
    <type>transmission_interface/SimpleTransmission</type>
    <joint name="joint_a4">
      <hardwareInterface>PositionJointInterface</hardwareInterface>
    </joint>
    <actuator name="motor4">
      <mechanicalReduction>1</mechanicalReduction>
    </actuator>
  </transmission>
  <transmission name="tran5">
    <type>transmission_interface/SimpleTransmission</type>
    <joint name="joint_a5">
      <hardwareInterface>PositionJointInterface</hardwareInterface>
    </joint>
    <actuator name="motor5">
      <mechanicalReduction>1</mechanicalReduction>
    </actuator>
  </transmission>
  <transmission name="tran6">
    <type>transmission_interface/SimpleTransmission</type>
    <joint name="joint_a6">
      <hardwareInterface>PositionJointInterface</hardwareInterface>
    </joint>
    <actuator name="motor6">
      <mechanicalReduction>1</mechanicalReduction>
    </actuator>
  </transmission>
  <!-- end of transmission list -->
  <!-- Gazebo-specific link properties -->
  <gazebo reference="base_link">
    <material>Gazebo/Orange</material>
    <turnGravityOff>true</turnGravityOff>
  </gazebo>
  <gazebo reference="link_1">
    <material>Gazebo/Orange</material>
    <turnGravityOff>true</turnGravityOff>
  </gazebo>
  <gazebo reference="link_2">
    <material>Gazebo/Orange</material>
    <turnGravityOff>true</turnGravityOff>
  </gazebo>
  <gazebo reference="link_3">
    <material>Gazebo/Orange</material>
    <turnGravityOff>true</turnGravityOff>
  </gazebo>
  <gazebo reference="link_4">
    <material>Gazebo/Orange</material>
    <turnGravityOff>true</turnGravityOff>
  </gazebo>
  <gazebo reference="link_5">
    <material>Gazebo/Orange</material>
    <turnGravityOff>true</turnGravityOff>
  </gazebo>
  <gazebo reference="link_6">
    <material>Gazebo/Black</material>
    <turnGravityOff>true</turnGravityOff>
  </gazebo>
  <!-- ros_control plugin -->
  <gazebo>
    <plugin filename="libgazebo_ros_control.so" name="gazebo_ros_control">
      <robotNamespace>/</robotNamespace>
      <robotSimType>gazebo_ros_control/DefaultRobotHWSim</robotSimType>
    </plugin>
  </gazebo>
  <!-- Fix robot to Gazebo world -->
  <link name="world"/>
  <joint name="world-base_link-fixed" type="fixed">
    <parent link="world"/>
    <child link="base_link"/>
  </joint>
</robot>
